<?xml version="1.0"?>
<robot name="panporter" xmlns:xacro="http://www.ros.org/wiki/xacro">

<!-- * * * link definitions * * * -->
  <link name="base_link">
    <pose>0 0 0.35 0 0 0</pose>
    <visual>
      <geometry>
	      <cylinder length="0.4" radius="0.3"/>
      </geometry>
      <origin rpy="1.570796327 0 0" xyz="0 0 0"/>
      <material name="yellow">
        <color rgba="1 1 0 0.4"/>
      </material>
    </visual>
    <collision>
      <geometry>
	      <cylinder length="0.4" radius="0.3"/>
      </geometry>
      <origin rpy="1.570796327 0 0" xyz="0 0 0"/>
      <material name="yellow">
        <color rgba="1 1 0 0.4"/>
      </material>
    </collision>
    <inertial>
	    <mass value="10.0"/>
	    <inertia ixx="1.0" ixy="0.0" ixz="0.0" iyy="1.0" iyz="0.0" izz="1.0"/>
      <origin rpy="1.570796327 0 0" xyz="0 0 0"/>
    </inertial>
  </link>

  <!-- <gazebo reference="base_link">
    <kp> 1000000.0</kp>
    <kd> 0.0 </kd>
    <mu1> 10.0 </mu1>
    <mu2> 10.0 </mu2>
  </gazebo> -->

  <joint name="prism_blue_joint" type="prismatic">
    <parent link="base_link"/>
    <child link="prism_left_blue_link"/>
    <origin xyz="0 0.2 0"/>
    <axis xyz="1 0 0" />
    <limit effort="300" velocity="1.0" lower="-0.1" upper="0.1"/>
    <safety_controller k_position="20" k_velocity="20" soft_lower_limit="-0.15" soft_upper_limit="0.15"/>
    <dynamics damping="50" friction="1.0"/>
  </joint>

  <transmission name="prism_blue_joint">
    <type>transmission_interface/SimpleTransmission</type>
    <joint name="prism_blue_joint">
      <hardwareInterface>EffortJointInterface</hardwareInterface>
    </joint>
    <actuator name="prism_blue_motor">
      <mechanicalReduction>1</mechanicalReduction>
      <hardwareInterface>EffortJointInterface</hardwareInterface>
    </actuator>
  </transmission>

  <link name="prism_left_blue_link">
    <pose>0 0 0.35 0 0 0</pose>
    <visual>
      <geometry>
	      <cylinder length="0.2" radius="0.02"/>
      </geometry>
      <origin rpy="0 -1.570796327 0" xyz="0 0 0"/>
      <material name="blue">
        <color rgba="0 0 1 1"/>
      </material>
    </visual>
    <collision>
      <geometry>
	      <cylinder length="0.2" radius="0.02"/>
      </geometry>
      <origin rpy="0 -1.570796327 0" xyz="0 0 0"/>
    </collision>
    <inertial>
	    <mass value="0.1"/>
	    <inertia ixx="0.01" ixy="0.0" ixz="0.0" iyy="0.01" iyz="0.0" izz="0.01"/>
    </inertial>
  </link>

  <joint name="prism_right_blue_joint" type="fixed">
    <parent link="prism_left_blue_link"/>
    <child link="prism_right_blue_link"/>
    <origin xyz="0 -0.4 0"/>
  </joint>

    <link name="prism_right_blue_link">
    <pose>0 0 0.35 0 0 0</pose>
    <visual>
      <geometry>
	      <cylinder length="0.2" radius="0.02"/>
      </geometry>
      <origin rpy="0 1.570796327 0" xyz="0 0 0"/>
      <material name="blue">
        <color rgba="0 0 1 1"/>
      </material>
    </visual>
    <collision>
      <geometry>
	      <cylinder length="0.2" radius="0.02"/>
      </geometry>
      <origin rpy="0 -1.570796327 0" xyz="0 0 0"/>
    </collision>
    <inertial>
	    <mass value="0.1"/>
	    <inertia ixx="0.01" ixy="0.0" ixz="0.0" iyy="0.01" iyz="0.0" izz="0.01"/>
    </inertial>
  </link>

  <joint name="wheel_left_joint" type="continuous">
    <parent link="prism_left_blue_link"/>
    <child link="wheel_left_link"/>
    <origin xyz="0 0.1 0"/>
    <axis xyz="0 1 0" />
    <limit effort="300" velocity="10000"/>
    <dynamics damping="50" friction="1"/>
  </joint>

  <transmission name="wheel_left_trans">
    <type>transmission_interface/SimpleTransmission</type>
    <joint name="wheel_left_joint">
      <hardwareInterface>EffortJointInterface</hardwareInterface>
    </joint>
    <actuator name="wheel_left_motor">
      <mechanicalReduction>10</mechanicalReduction>
      <hardwareInterface>EffortJointInterface</hardwareInterface>
    </actuator>
  </transmission>

  <link name="wheel_left_link">
    <pose>0 0 0.35 0 0 0</pose>
    <visual>
      <geometry>
	      <cylinder length="0.04" radius="0.35"/>
      </geometry>
      <origin rpy="1.570796327 0 0" xyz="0 0 0"/>
      <material name="red">
        <color rgba="1 0 0 0.4"/>
      </material>
    </visual>
    <collision>
      <geometry>
	      <cylinder length="0.04" radius="0.35"/>
      </geometry>
      <origin rpy="1.570796327 0 0" xyz="0 0 0"/>
    </collision>
    <inertial>
	    <mass value="1"/>
	    <inertia ixx="0.5" ixy="0.0" ixz="0.0" iyy="0.5" iyz="0.0" izz="0.5"/>
    </inertial>
  </link>

  <!-- <gazebo reference="wheel_left_link">
    <material>Gazebo/Green</material>
  </gazebo> -->

  <joint name="wheel_right_joint" type="continuous">
    <parent link="prism_right_blue_link"/>
    <child link="wheel_right_link"/>
    <origin xyz="0 -0.1 0"/>
    <axis xyz="0 1 0" />
    <limit effort="300" velocity="10000"/> <!-- lower="-1.570796327" upper="1.570796327"/> -->
    <dynamics damping="50" friction="1"/>
  </joint>

  <transmission name="wheel_right_trans">
    <type>transmission_interface/SimpleTransmission</type>
    <joint name="wheel_right_joint">
      <hardwareInterface>EffortJointInterface</hardwareInterface>
    </joint>
    <actuator name="wheel_right_motor">
      <mechanicalReduction>10</mechanicalReduction>
      <hardwareInterface>EffortJointInterface</hardwareInterface>
    </actuator>
  </transmission>

  <link name="wheel_right_link">
    <pose>0 0 0.35 0 0 0</pose>
    <visual>
      <geometry>
	      <cylinder length="0.04" radius="0.35"/>
      </geometry>
      <origin rpy="1.570796327 0 0" xyz="0 0 0"/>
      <material name="red">
        <color rgba="1 0 0 0.4"/>
      </material>
    </visual>
    <collision>
      <geometry>
	      <cylinder length="0.04" radius="0.35"/>
      </geometry>
      <origin rpy="1.570796327 0 0" xyz="0 0 0"/>
    </collision>
    <inertial>
	    <mass value="1"/>
	    <inertia ixx="0.5" ixy="0.0" ixz="0.0" iyy="0.5" iyz="0.0" izz="0.5"/>
    </inertial>
  </link>

  <!-- <gazebo reference="wheel_left_link">
    <material>Gazebo/Red</material>
  </gazebo> -->

  <gazebo>
    <plugin filename="libgazebo_ros_diff_drive.so" name="differential_drive_controller">
      <alwaysOn>true</alwaysOn>
      <updateRate>100</updateRate>
      <leftJoint>wheel_left_joint</leftJoint>
      <rightJoint>wheel_right_joint</rightJoint>
      <torque>5</torque>
      <wheelSeparation>0.4</wheelSeparation>
      <wheelDiameter>0.7</wheelDiameter>
      <commandTopic>cmd_vel</commandTopic>
      <odometryTopic>odom</odometryTopic>
      <odometryFrame>odom</odometryFrame>
      <odometrySource>world</odometrySource>
      <robotBaseFrame>base_link</robotBaseFrame>
      <publishTf>true</publishTf>
      <publishOdomTF>true</publishOdomTF>
      <publishWheelTF>true</publishWheelTF>
      <publishWheelJointState>true</publishWheelJointState>
      <wheelAcceleration>0</wheelAcceleration>
      <wheelTorque>5</wheelTorque>
      <rosDebugLevel>na</rosDebugLevel>
      <legacyMode>true</legacyMode>
    </plugin>
  </gazebo>

  <gazebo>
    <plugin name="gazebo_ros_control" filename="libgazebo_ros_control.so">
      <robotNamespace>/panporter</robotNamespace>
      <robotSimType>gazebo_ros_control/DefaultRobotHWSim</robotSimType>
      <controlPeriod>0.002</controlPeriod>
      <legacyModeNS>false</legacyModeNS>
    </plugin>
    <plugin name='gazebo_ros_imu' filename='libhector_gazebo_ros_imu.so'>
      <alwaysOn>true</alwaysOn>
      <updateRate>200.0</updateRate>
      <bodyName>base_link</bodyName>
      <topicName>/imu_bosch/data_raw</topicName>
      <gaussianNoise>0.02</gaussianNoise>
      <xyzOffsets>0 0 0</xyzOffsets>
      <rpyOffsets>0 0 0</rpyOffsets>
    </plugin>
  </gazebo>

  <!-- base_link -->
	<gazebo reference="base_link">
		<material value="Gazebo/Grey"/>
	</gazebo>

  <!-- prism_left_blue_link -->
	<gazebo reference="prism_left_blue_link">
		<material value="Gazebo/Blue"/>
	</gazebo>

  <!-- prism_right_blue_link -->
	<gazebo reference="prism_right_blue_link">
		<material value="Gazebo/Blue"/>
	</gazebo>

  <!-- wheel_left_link -->
	<gazebo reference="wheel_left_link">
		<material value="Gazebo/Red"/>
	</gazebo>

  <!-- wheel_right_link -->
	<gazebo reference="wheel_right_link">
		<material value="Gazebo/Red"/>
	</gazebo>

</robot>