<?xml version="1.0"?>
<robot name="panporter" xmlns:xacro="http://www.ros.org/wiki/xacro">

<!-- * * * link definitions * * * -->
  <link name="base_link">
    <pose>0 0 0.35 0 0 0</pose>
    <visual>
      <geometry>
        <mesh filename="package://panporter_pkg/urdf/base_link.stl" scale="1.0 1.0 1.0"/>
      </geometry>
      <origin rpy="1.570796327 0 0" xyz="0 0 0"/>
      <material name="yellow">
        <color rgba="1 1 0 0.4"/>
      </material>
    </visual>
    <collision>
      <!-- <geometry>
	      <cylinder length="0.4" radius="0.3"/>
      </geometry> -->
      <geometry>
        <mesh filename="package://panporter_pkg/urdf/base_link.stl" scale="1.0 1.0 1.0"/>
      </geometry>
      <origin rpy="1.570796327 0 0" xyz="0 0 0"/>
      <material name="yellow">
        <color rgba="1 1 0 0.4"/>
      </material>
    </collision>
    <inertial>
	    <mass value="10.0"/>
	    <inertia ixx="1.0" ixy="0.0" ixz="0.0" iyy="1.0" iyz="0.0" izz="1.0"/>
      <origin rpy="1.570796327 0 0" xyz="0 0 0"/>
    </inertial>
  </link>

  <!-- <gazebo reference="base_link">
    <kp> 1000000.0</kp>
    <kd> 0.0 </kd>
    <mu1> 10.0 </mu1>
    <mu2> 10.0 </mu2>
  </gazebo> -->

  <joint name="prism_blue_joint" type="prismatic">
    <parent link="base_link"/>
    <child link="prism_left_blue_link"/>
    <origin xyz="0 0.2 0"/>
    <axis xyz="1 0 0" />
    <limit effort="300" velocity="1.0" lower="-0.1" upper="0.1"/>
    <safety_controller k_position="20" k_velocity="20" soft_lower_limit="-0.15" soft_upper_limit="0.15"/>
    <dynamics damping="50" friction="1.0"/>
  </joint>

  <transmission name="prism_blue_joint">
    <type>transmission_interface/SimpleTransmission</type>
    <joint name="prism_blue_joint">
      <hardwareInterface>EffortJointInterface</hardwareInterface>
    </joint>
    <actuator name="prism_blue_motor">
      <mechanicalReduction>1</mechanicalReduction>
      <hardwareInterface>EffortJointInterface</hardwareInterface>
    </actuator>
  </transmission>

  <link name="prism_left_blue_link">
    <pose>0 0 0.35 0 0 0</pose>
    <visual>
      <geometry>
	      <cylinder length="0.2" radius="0.02"/>
      </geometry>
      <origin rpy="0 -1.570796327 0" xyz="0 0 0"/>
      <material name="blue">
        <color rgba="0 0 1 1"/>
      </material>
    </visual>
    <collision>
      <geometry>
	      <cylinder length="0.2" radius="0.02"/>
      </geometry>
      <origin rpy="0 -1.570796327 0" xyz="0 0 0"/>
    </collision>
    <inertial>
	    <mass value="0.1"/>
	    <inertia ixx="0.01" ixy="0.0" ixz="0.0" iyy="0.01" iyz="0.0" izz="0.01"/>
    </inertial>
  </link>

  <joint name="prism_right_blue_joint" type="fixed">
    <parent link="prism_left_blue_link"/>
    <child link="prism_right_blue_link"/>
    <origin xyz="0 -0.4 0"/>
  </joint>

    <link name="prism_right_blue_link">
    <pose>0 0 0.35 0 0 0</pose>
    <visual>
      <geometry>
	      <cylinder length="0.2" radius="0.02"/>
      </geometry>
      <origin rpy="0 1.570796327 0" xyz="0 0 0"/>
      <material name="blue">
        <color rgba="0 0 1 1"/>
      </material>
    </visual>
    <collision>
      <geometry>
	      <cylinder length="0.2" radius="0.02"/>
      </geometry>
      <origin rpy="0 -1.570796327 0" xyz="0 0 0"/>
    </collision>
    <inertial>
	    <mass value="0.1"/>
	    <inertia ixx="0.01" ixy="0.0" ixz="0.0" iyy="0.01" iyz="0.0" izz="0.01"/>
    </inertial>
  </link>

  <joint name="wheel_left_joint" type="continuous">
    <parent link="prism_left_blue_link"/>
    <child link="wheel_left_link"/>
    <origin xyz="0 0.1 0"/>
    <axis xyz="0 1 0" />
    <limit effort="300" velocity="10000"/>
    <dynamics damping="50" friction="1"/>
  </joint>

  <transmission name="wheel_left_trans">
    <type>transmission_interface/SimpleTransmission</type>
    <joint name="wheel_left_joint">
      <hardwareInterface>EffortJointInterface</hardwareInterface>
    </joint>
    <actuator name="wheel_left_motor">
      <mechanicalReduction>10</mechanicalReduction>
      <hardwareInterface>EffortJointInterface</hardwareInterface>
    </actuator>
  </transmission>

  <link name="wheel_left_link">
    <pose>0 0 0.35 0 0 0</pose>
    <visual>
      <geometry>
	      <cylinder length="0.04" radius="0.35"/>
      </geometry>
      <origin rpy="1.570796327 0 0" xyz="0 0 0"/>
      <material name="red">
        <color rgba="1 0 0 0.4"/>
      </material>
    </visual>
    <collision>
      <geometry>
	      <cylinder length="0.04" radius="0.35"/>
      </geometry>
      <origin rpy="1.570796327 0 0" xyz="0 0 0"/>
    </collision>
    <inertial>
	    <mass value="1"/>
	    <inertia ixx="0.5" ixy="0.0" ixz="0.0" iyy="0.5" iyz="0.0" izz="0.5"/>
    </inertial>
  </link>

  <!-- <gazebo reference="wheel_left_link">
    <material>Gazebo/Green</material>
  </gazebo> -->

  <joint name="wheel_right_joint" type="continuous">
    <parent link="prism_right_blue_link"/>
    <child link="wheel_right_link"/>
    <origin xyz="0 -0.1 0"/>
    <axis xyz="0 1 0" />
    <limit effort="300" velocity="10000"/> <!-- lower="-1.570796327" upper="1.570796327"/> -->
    <dynamics damping="50" friction="1"/>
  </joint>

  <transmission name="wheel_right_trans">
    <type>transmission_interface/SimpleTransmission</type>
    <joint name="wheel_right_joint">
      <hardwareInterface>EffortJointInterface</hardwareInterface>
    </joint>
    <actuator name="wheel_right_motor">
      <mechanicalReduction>10</mechanicalReduction>
      <hardwareInterface>EffortJointInterface</hardwareInterface>
    </actuator>
  </transmission>

  <link name="wheel_right_link">
    <pose>0 0 0.35 0 0 0</pose>
    <visual>
      <geometry>
	      <cylinder length="0.04" radius="0.35"/>
      </geometry>
      <origin rpy="1.570796327 0 0" xyz="0 0 0"/>
      <material name="red">
        <color rgba="1 0 0 0.4"/>
      </material>
    </visual>
    <collision>
      <geometry>
	      <cylinder length="0.04" radius="0.35"/>
      </geometry>
      <origin rpy="1.570796327 0 0" xyz="0 0 0"/>
    </collision>
    <inertial>
	    <mass value="1"/>
	    <inertia ixx="0.5" ixy="0.0" ixz="0.0" iyy="0.5" iyz="0.0" izz="0.5"/>
    </inertial>
  </link>

  <!-- <gazebo reference="wheel_left_link">
    <material>Gazebo/Red</material>
  </gazebo> -->

  <joint name="imu_joint" type="fixed">
    <parent link="base_link"/>
    <child link="imu_link"/>
    <origin xyz="0.0 0 0.068" rpy="0 0 0"/>
  </joint>

  <link name="imu_link"/>

  <joint name="scan_joint" type="fixed">
    <parent link="base_link"/>
    <child link="base_scan"/>
    <origin xyz="-0.064 0 0.122" rpy="0 0 0"/>
  </joint>

  <link name="base_scan">
    <visual>
      <origin xyz="0 0 0" rpy="0 0 0"/>
      <geometry>
        <mesh filename="package://turtlebot3_description/meshes/sensors/lds.stl" scale="0.001 0.001 0.001"/>
      </geometry>
      <material name="dark"/>
    </visual>

    <collision>
      <origin xyz="0.015 0 -0.0065" rpy="0 0 0"/>
      <geometry>
        <cylinder length="0.0315" radius="0.055"/>
      </geometry>
    </collision>

    <inertial>
      <mass value="0.114" />
      <origin xyz="0 0 0" />
      <inertia ixx="0.001" ixy="0.0" ixz="0.0"
               iyy="0.001" iyz="0.0"
               izz="0.001" />
    </inertial>
  </link>

  <joint name="camera_joint" type="fixed">
    <origin xyz="0.064 -0.065 0.094" rpy="0 0 0"/>
    <parent link="base_link"/>
    <child link="camera_link"/>
  </joint>

  <link name="camera_link">
    <visual>
     <origin xyz="0 0 0" rpy="1.57 0 1.57"/>
      <geometry>
       <mesh filename="package://turtlebot3_description/meshes/sensors/r200.dae" />
      </geometry>
    </visual>
    <collision>
      <origin xyz="0.003 0.065 0.007" rpy="0 0 0"/>
      <geometry>
        <box size="0.012 0.132 0.020"/>
      </geometry>
    </collision>

    <!-- This inertial field needs doesn't contain reliable data!! -->
<!--   <inertial>
      <mass value="0.564" />
      <origin xyz="0 0 0" />
      <inertia ixx="0.003881243" ixy="0.0" ixz="0.0"
               iyy="0.000498940" iyz="0.0"
               izz="0.003879257" />
    </inertial>-->
  </link>

  <gazebo>
    <plugin filename="libgazebo_ros_diff_drive.so" name="differential_drive_controller">
      <alwaysOn>true</alwaysOn>
      <updateRate>100</updateRate>
      <leftJoint>wheel_left_joint</leftJoint>
      <rightJoint>wheel_right_joint</rightJoint>
      <torque>5</torque>
      <wheelSeparation>0.4</wheelSeparation>
      <wheelDiameter>0.7</wheelDiameter>
      <commandTopic>cmd_vel</commandTopic>
      <odometryTopic>odom</odometryTopic>
      <odometryFrame>odom</odometryFrame>
      <odometrySource>world</odometrySource>
      <robotBaseFrame>base_link</robotBaseFrame>
      <publishTf>true</publishTf>
      <publishOdomTF>true</publishOdomTF>
      <publishWheelTF>true</publishWheelTF>
      <publishWheelJointState>true</publishWheelJointState>
      <wheelAcceleration>0</wheelAcceleration>
      <wheelTorque>5</wheelTorque>
      <rosDebugLevel>na</rosDebugLevel>
      <legacyMode>true</legacyMode>
    </plugin>
  </gazebo>

  <gazebo>
    <plugin name="gazebo_ros_control" filename="libgazebo_ros_control.so">
      <robotNamespace>/panporter</robotNamespace>
      <robotSimType>gazebo_ros_control/DefaultRobotHWSim</robotSimType>
      <controlPeriod>0.002</controlPeriod>
      <legacyModeNS>false</legacyModeNS>
    </plugin>
    <plugin name='gazebo_ros_imu' filename='libhector_gazebo_ros_imu.so'>
      <alwaysOn>true</alwaysOn>
      <updateRate>200.0</updateRate>
      <bodyName>base_link</bodyName>
      <topicName>/imu_bosch/data_raw</topicName>
      <gaussianNoise>0.02</gaussianNoise>
      <xyzOffsets>0 0 0</xyzOffsets>
      <rpyOffsets>0 0 0</rpyOffsets>
    </plugin>
  </gazebo>

  <!-- base_link -->
	<gazebo reference="base_link">
		<material value="Gazebo/Grey"/>
	</gazebo>

  <!-- prism_left_blue_link -->
	<gazebo reference="prism_left_blue_link">
		<material value="Gazebo/Blue"/>
	</gazebo>

  <!-- prism_right_blue_link -->
	<gazebo reference="prism_right_blue_link">
		<material value="Gazebo/Blue"/>
	</gazebo>

  <!-- wheel_left_link -->
	<gazebo reference="wheel_left_link">
		<material value="Gazebo/Red"/>
	</gazebo>

  <!-- wheel_right_link -->
	<gazebo reference="wheel_right_link">
		<material value="Gazebo/Red"/>
	</gazebo>

  <gazebo>
    <plugin name="imu_plugin" filename="libgazebo_ros_imu.so">
      <alwaysOn>true</alwaysOn>
      <bodyName>imu_link</bodyName>
      <frameName>imu_link</frameName>
      <topicName>imu</topicName>
      <serviceName>imu_service</serviceName>
      <gaussianNoise>0.0</gaussianNoise>
      <updateRate>0</updateRate>
      <imu>
        <noise>
          <type>gaussian</type>
          <rate>
            <mean>0.0</mean>
            <stddev>2e-4</stddev>
            <bias_mean>0.0000075</bias_mean>
            <bias_stddev>0.0000008</bias_stddev>
          </rate>
          <accel>
            <mean>0.0</mean>
            <stddev>1.7e-2</stddev>
            <bias_mean>0.1</bias_mean>
            <bias_stddev>0.001</bias_stddev>
          </accel>
        </noise>
      </imu>
    </plugin>
  </gazebo>

  <gazebo reference="base_scan">
    <material>Gazebo/FlatBlack</material>
    <sensor type="ray" name="lds_lfcd_sensor">
      <pose>0 0 0 0 0 0</pose>
      <visualize>true</visualize>
      <update_rate>5</update_rate>
      <ray>
        <scan>
          <horizontal>
            <samples>360</samples>
            <resolution>1</resolution>
            <min_angle>0.0</min_angle>
            <max_angle>6.28319</max_angle>
          </horizontal>
        </scan>
        <range>
          <min>0.120</min>
          <max>3.5</max>
          <resolution>0.015</resolution>
        </range>
        <noise>
          <type>gaussian</type>
          <mean>0.0</mean>
          <stddev>0.01</stddev>
        </noise>
      </ray>
      <plugin name="gazebo_ros_lds_lfcd_controller" filename="libgazebo_ros_laser.so">
        <topicName>scan</topicName>
        <frameName>base_scan</frameName>
      </plugin>
    </sensor>
  </gazebo>

  <!--link : https://www.raspberrypi.org/documentation/hardware/camera/-->
  <gazebo reference="camera_rgb_frame">
    <sensor type="camera" name="Pi Camera">
      <always_on>true</always_on>
      <visualize>true</visualize>
      <camera>
          <horizontal_fov>1.085595</horizontal_fov>
          <image>
              <width>640</width>
              <height>480</height>
              <format>R8G8B8</format>
          </image>
          <clip>
              <near>0.03</near>
              <far>100</far>
          </clip>
      </camera>
      <plugin name="camera_controller" filename="libgazebo_ros_camera.so">
        <alwaysOn>true</alwaysOn>
        <updateRate>30.0</updateRate>
        <cameraName>camera</cameraName>
        <frameName>camera_rgb_optical_frame</frameName>
        <imageTopicName>rgb/image_raw</imageTopicName>
        <cameraInfoTopicName>rgb/camera_info</cameraInfoTopicName>
        <hackBaseline>0.07</hackBaseline>
        <distortionK1>0.0</distortionK1>
        <distortionK2>0.0</distortionK2>
        <distortionK3>0.0</distortionK3>
        <distortionT1>0.0</distortionT1>
        <distortionT2>0.0</distortionT2>
      </plugin>
    </sensor>
  </gazebo>

</robot>